File: Job Rotation 1/MR01.csv
Position (mm),Force (N),Strain (%),Time (min),Tensão (MPa),
0,1.67,0,0.00346,,
0.009,53.3,0.00133,0.00555,,
0.021,224,0.00517,0.01,,
0.0259,261,0.006,0.0145,,
0.03,295,0.00683,0.019,,
0.035,325,0.0075,0.0235,,
0.039,354,0.00811,0.0279,,
0.044,383,0.00867,0.0324,,
0.048,409,0.00917,0.0369,,
0.0524,434,0.0095,0.0414,,
0.057,457,0.00983,0.0458,,
0.0619,481,0.0103,0.0503,,
0.066,503,0.0107,0.0548,,
0.0703,527,0.0111,0.0593,,
0.075,548,0.0115,0.0637,,
0.079,562,0.0117,0.0682,,
0.084,562,0.0112,0.0727,,
0.0889,519,0.00918,0.0772,,
0.093,508,0.00817,0.0817,,
0.097,506,0.00754,0.0861,,
0.102,505,0.007,0.0906,,
0.106,503,0.00633,0.0951,,
0.111,500,0.00567,0.0996,,
0.115,498,0.00509,0.104,,
0.12,497,0.0045,0.109,,
0.124,507,0.00417,0.113,,
0.129,527,0.00433,0.117,,
0.133,545,0.00433,0.122,,
0.138,555,0.00417,0.126,,
0.142,558,0.00383,0.131,,
0.147,562,0.00334,0.135,,
0.151,565,0.003,0.14,,
0.155,568,0.0025,0.144,,
0.16,573,0.002,0.149,,
0.165,577,0.00152,0.153,,
0.169,578,0.001,0.158,,
0.173,582,0.0005,0.162,,
0.178,585,-8.84E-05,0.167,,
0.182,587,-0.000667,0.171,,
0.187,590,-0.00133,0.176,,
0.191,595,-0.00167,0.18,,
0.196,598,-0.00217,0.185,,
0.2,602,-0.00267,0.189,,
0.205,608,-0.00317,0.194,,
0.209,615,-0.0035,0.198,,
0.214,622,-0.00367,0.203,,
0.218,632,-0.00383,0.207,,
0.223,641,-0.00394,0.211,,
0.227,648,-0.004,0.216,,
0.232,658,-0.004,0.22,,
0.236,668,-0.00383,0.225,,
0.241,678,-0.00367,0.229,,
0.245,695,-0.00333,0.234,,
0.25,713,-0.00283,0.238,,
0.254,730,-0.00217,0.243,,
0.258,745,-0.0015,0.247,,
0.263,761,-0.001,0.252,,
0.268,777,-0.000352,0.256,,
0.272,790,2.30E-05,0.261,,
0.276,804,0.000667,0.265,,
0.281,818,0.001,0.27,,
0.285,831,0.00147,0.274,,
0.29,845,0.00183,0.279,,
0.294,858,0.00233,0.283,,
0.299,874,0.00267,0.288,,
0.303,890,0.00317,0.292,,
0.308,906,0.0035,0.297,,
0.312,922,0.004,0.301,,
0.317,935,0.00438,0.305,,
0.321,950,0.00483,0.31,,
0.326,965,0.00533,0.314,,
0.33,978,0.00567,0.319,,
0.335,992,0.006,0.323,,
0.339,1010,0.0065,0.328,,
0.344,1020,0.00683,0.332,,
0.348,1030,0.00733,0.337,,
0.353,1050,0.00767,0.341,,
0.357,1060,0.00817,0.346,,
0.361,1070,0.00858,0.35,,
0.366,1080,0.009,0.355,,
0.371,1100,0.0095,0.359,,
0.375,1110,0.00986,0.364,,
0.379,1120,0.0103,0.368,,
0.384,1130,0.0109,0.373,,
0.388,1140,0.0113,0.377,,
0.393,1160,0.0117,0.382,,
0.397,1170,0.0123,0.386,,
0.402,1180,0.0127,0.391,,
0.406,1190,0.0132,0.395,,
0.411,1200,0.0137,0.4,,
0.415,1220,0.0142,0.404,,
0.42,1230,0.0146,0.408,,
0.424,1240,0.015,0.413,,
0.429,1260,0.0155,0.417,,
0.433,1270,0.016,0.422,,
0.437,1280,0.0164,0.426,,
0.442,1300,0.017,0.431,,
0.447,1310,0.0174,0.435,,
0.451,1320,0.0178,0.44,,
0.455,1340,0.0183,0.444,,
0.46,1350,0.0188,0.449,,
0.464,1370,0.0193,0.453,,
0.469,1380,0.0198,0.458,,
0.473,1390,0.0202,0.462,,
0.478,1410,0.0207,0.467,,
0.482,1420,0.0212,0.471,,
0.487,1440,0.0217,0.476,,
0.491,1450,0.0221,0.48,,
0.496,1470,0.0225,0.485,,
0.5,1480,0.023,0.489,,
0.505,1500,0.0235,0.494,,
0.509,1510,0.024,0.498,,
0.514,1520,0.0243,0.502,,
0.518,1540,0.0248,0.507,,
0.523,1550,0.0252,0.511,,
0.527,1570,0.0257,0.516,,
0.532,1580,0.026,0.52,,
0.536,1590,0.0265,0.525,,
0.54,1610,0.027,0.529,,
0.545,1620,0.0273,0.534,,
0.55,1640,0.0278,0.538,,
0.554,1650,0.0282,0.543,,
0.558,1670,0.0287,0.547,,
0.563,1680,0.029,0.552,,
0.567,1690,0.0294,0.556,,
0.572,1710,0.0298,0.561,,
0.576,1720,0.0303,0.565,,
0.581,1730,0.0307,0.57,,
0.585,1750,0.0311,0.574,,
0.59,1760,0.0315,0.579,,
0.594,1780,0.0318,0.583,,
0.599,1790,0.0323,0.588,,
0.603,1800,0.0327,0.592,,
0.608,1820,0.033,0.596,,
0.612,1830,0.0333,0.601,,
0.617,1840,0.0338,0.605,,
0.621,1860,0.0342,0.61,,
0.626,1870,0.0345,0.614,,
0.63,1880,0.0349,0.619,,
0.635,1890,0.0353,0.623,,
0.639,1910,0.0357,0.628,,
0.643,1920,0.0362,0.632,,
0.648,1940,0.0365,0.637,,
0.653,1950,0.0368,0.641,,
0.657,1960,0.0373,0.646,,
0.661,1980,0.0377,0.65,,
0.666,1990,0.038,0.655,,
0.67,2000,0.0385,0.659,,
0.675,2020,0.0388,0.664,,
0.679,2030,0.0393,0.668,,
0.684,2040,0.0397,0.673,,
0.688,2060,0.04,0.677,,
0.693,2070,0.0403,0.682,,
0.697,2080,0.0408,0.686,,
0.702,2100,0.0412,0.691,,
0.706,2110,0.0415,0.695,,
0.711,2130,0.042,0.699,,
0.715,2140,0.0423,0.704,,
0.72,2150,0.0428,0.708,,
0.724,2170,0.0432,0.713,,
0.728,2180,0.0436,0.717,,
0.733,2200,0.044,0.722,,
0.738,2210,0.0443,0.726,,
0.742,2220,0.0448,0.731,,
0.746,2240,0.0452,0.735,,
0.751,2250,0.0456,0.74,,
0.755,2270,0.046,0.744,,
0.76,2280,0.0463,0.749,,
0.764,2300,0.0468,0.753,,
0.769,2310,0.0472,0.758,,
0.773,2320,0.0477,0.762,,
0.778,2340,0.048,0.767,,
0.782,2350,0.0483,0.771,,
0.787,2370,0.0488,0.776,,
0.791,2380,0.0492,0.78,,
0.796,2400,0.0497,0.785,,
0.8,2410,0.0501,0.789,,
0.805,2430,0.0505,0.793,,
0.809,2440,0.051,0.798,,
0.814,2460,0.0513,0.802,,
0.818,2470,0.0518,0.807,,
0.823,2490,0.0522,0.811,,
0.827,2500,0.0527,0.816,,
0.831,2520,0.053,0.82,,
0.836,2530,0.0535,0.825,,
0.841,2550,0.0538,0.829,,
0.845,2560,0.0543,0.834,,
0.849,2580,0.0547,0.838,,
0.854,2590,0.0552,0.843,,
0.859,2610,0.0555,0.847,,
0.863,2620,0.056,0.852,,
0.867,2640,0.0565,0.856,,
0.872,2650,0.0568,0.861,,
0.876,2670,0.0573,0.865,,
0.881,2680,0.0577,0.87,,
0.885,2700,0.0582,0.874,,
0.89,2720,0.0585,0.879,,
0.894,2730,0.059,0.883,,
0.899,2750,0.0595,0.887,,
0.903,2760,0.0598,0.892,,
0.908,2780,0.0602,0.896,,
0.912,2800,0.0607,0.901,,
0.917,2810,0.0612,0.905,,
0.921,2830,0.0615,0.91,,
0.926,2840,0.062,0.914,,
0.93,2860,0.0623,0.919,,
0.934,2880,0.0628,0.923,,
0.939,2890,0.0632,0.928,,
0.944,2910,0.0636,0.932,,
0.948,2930,0.064,0.937,,
0.952,2940,0.0645,0.941,,
0.957,2960,0.0648,0.946,,
0.961,2980,0.0653,0.95,,
0.966,2990,0.0657,0.955,,
0.97,3010,0.0662,0.959,,
0.975,3030,0.0667,0.964,,
0.979,3040,0.067,0.968,,
0.984,3060,0.0673,0.973,,
0.988,3080,0.0678,0.977,,
0.993,3090,0.0682,0.981,,
0.997,3110,0.0687,0.986,,
1,3120,0.0692,0.99,,
1.01,3140,0.0695,0.995,,
1.01,3160,0.07,0.999,,
1.02,3170,0.0703,1,,
1.02,3190,0.0708,1.01,,
1.02,3210,0.0712,1.01,,
1.03,3230,0.0717,1.02,,
1.03,3240,0.072,1.02,,
1.04,3260,0.0725,1.03,,
1.04,3280,0.0729,1.03,,
1.05,3290,0.0733,1.04,,
1.05,3310,0.0738,1.04,,
1.06,3330,0.0742,1.04,,
1.06,3350,0.0747,1.05,,
1.06,3360,0.075,1.05,,
1.07,3380,0.0755,1.06,,
1.07,3400,0.0759,1.06,,
1.08,3420,0.0763,1.07,,
1.08,3430,0.0767,1.07,,
1.09,3450,0.0772,1.08,,
1.09,3470,0.0777,1.08,,
1.1,3490,0.078,1.08,,
1.1,3500,0.0785,1.09,,
1.1,3520,0.0788,1.09,,
1.11,3540,0.0793,1.1,,
1.11,3560,0.0798,1.1,,
1.12,3580,0.0802,1.11,,
1.12,3590,0.0807,1.11,,
1.13,3610,0.0811,1.12,,
1.13,3630,0.0815,1.12,,
1.14,3650,0.082,1.12,,
1.14,3670,0.0825,1.13,,
1.15,3690,0.0828,1.13,,
1.15,3700,0.0833,1.14,,
1.15,3720,0.0837,1.14,,
1.16,3740,0.0842,1.15,,
1.16,3760,0.0846,1.15,,
1.17,3780,0.085,1.16,,
1.17,3800,0.0855,1.16,,
1.18,3810,0.0858,1.17,,
1.18,3830,0.0865,1.17,,
1.19,3850,0.087,1.17,,
1.19,3870,0.0873,1.18,,
1.19,3890,0.0878,1.18,,
1.2,3910,0.0882,1.19,,
1.2,3930,0.0887,1.19,,
1.21,3950,0.0891,1.2,,
1.21,3960,0.0895,1.2,,
1.22,3980,0.09,1.21,,
1.22,4000,0.0905,1.21,,
1.23,4020,0.0908,1.21,,
1.23,4040,0.0913,1.22,,
1.23,4060,0.0918,1.22,,
1.24,4080,0.0922,1.23,,
1.24,4100,0.0927,1.23,,
1.25,4120,0.0932,1.24,,
1.25,4140,0.0936,1.24,,
1.26,4160,0.094,1.25,,
1.26,4170,0.0945,1.25,,
1.27,4190,0.095,1.25,,
1.27,4210,0.0953,1.26,,
1.27,4230,0.0958,1.26,,
1.28,4250,0.0963,1.27,,
1.28,4270,0.0968,1.27,,
1.29,4290,0.0972,1.28,,
1.29,4310,0.0977,1.28,,
1.3,4330,0.0982,1.29,,
1.3,4350,0.0985,1.29,,
1.31,4370,0.099,1.29,,
1.31,4390,0.0995,1.3,,
1.32,4410,0.1,1.3,,
1.32,4430,0.101,1.31,,
1.32,4450,0.101,1.31,,
1.33,4470,0.101,1.32,,
1.33,4480,0.102,1.32,,
1.34,4500,0.102,1.33,,
1.34,4530,0.103,1.33,,
1.35,4540,0.103,1.34,,
1.35,4560,0.104,1.34,,
1.36,4580,0.104,1.34,,
1.36,4610,0.105,1.35,,
1.36,4620,0.105,1.35,,
1.37,4640,0.106,1.36,,
1.37,4670,0.106,1.36,,
1.38,4680,0.106,1.37,,
1.38,4710,0.107,1.37,,
1.39,4730,0.108,1.38,,
1.39,4750,0.108,1.38,,
1.4,4770,0.108,1.38,,
1.4,4790,0.109,1.39,,
1.41,4810,0.109,1.39,,
1.41,4830,0.11,1.4,,
1.41,4850,0.11,1.4,,
1.42,4870,0.111,1.41,,
1.42,4890,0.112,1.41,,
1.43,4910,0.112,1.42,,
1.43,4930,0.112,1.42,,
1.44,4950,0.113,1.42,,
1.44,4970,0.113,1.43,,
1.45,4990,0.114,1.43,,
1.45,5020,0.114,1.44,,
1.45,5040,0.115,1.44,,
1.46,5060,0.115,1.45,,
1.46,5080,0.116,1.45,,
1.47,5100,0.116,1.46,,
1.47,5120,0.117,1.46,,
1.48,5140,0.117,1.46,,
1.48,5170,0.118,1.47,,
1.49,5190,0.118,1.47,,
1.49,5210,0.119,1.48,,
1.49,5230,0.119,1.48,,
1.5,5250,0.12,1.49,,
1.5,5270,0.12,1.49,,
1.51,5300,0.121,1.5,,
1.51,5320,0.122,1.5,,
1.52,5340,0.122,1.51,,
1.52,5360,0.123,1.51,,
1.53,5380,0.123,1.51,,
1.53,5410,0.124,1.52,,
1.53,5430,0.124,1.52,,
1.54,5450,0.125,1.53,,
1.54,5470,0.125,1.53,,
1.55,5490,0.126,1.54,,
1.55,5520,0.126,1.54,,
1.56,5540,0.127,1.55,,
1.56,5560,0.127,1.55,,
1.57,5580,0.128,1.55,,
1.57,5610,0.128,1.56,,
1.58,5630,0.129,1.56,,
1.58,5650,0.129,1.57,,
1.58,5670,0.13,1.57,,
1.59,5690,0.131,1.58,,
1.59,5720,0.131,1.58,,
1.6,5740,0.132,1.59,,
1.6,5760,0.132,1.59,,
1.61,5790,0.133,1.59,,
1.61,5810,0.133,1.6,,
1.62,5830,0.134,1.6,,
1.62,5850,0.134,1.61,,
1.62,5870,0.135,1.61,,
1.63,5900,0.135,1.62,,
1.63,5920,0.136,1.62,,
1.64,5940,0.137,1.63,,
1.64,5970,0.137,1.63,,
1.65,5990,0.138,1.64,,
1.65,6010,0.138,1.64,,
1.66,6040,0.139,1.64,,
1.66,6060,0.139,1.65,,
1.66,6080,0.14,1.65,,
1.67,6110,0.14,1.66,,
1.67,6130,0.141,1.66,,
1.68,6150,0.141,1.67,,
1.68,6170,0.142,1.67,,
1.69,6200,0.142,1.68,,
1.69,6220,0.143,1.68,,
1.7,6250,0.144,1.68,,
1.7,6270,0.144,1.69,,
1.7,6290,0.145,1.69,,
1.71,6320,0.145,1.7,,
1.71,6340,0.146,1.7,,
1.72,6360,0.147,1.71,,
1.72,6390,0.147,1.71,,
1.73,6410,0.148,1.72,,
1.73,6430,0.148,1.72,,
1.74,6460,0.149,1.72,,
1.74,6480,0.149,1.73,,
1.74,6500,0.15,1.73,,
1.75,6530,0.151,1.74,,
1.75,6550,0.151,1.74,,
1.76,6580,0.152,1.75,,
1.76,6600,0.152,1.75,,
1.77,6620,0.153,1.76,,
1.77,6650,0.154,1.76,,
1.78,6670,0.154,1.76,,
1.78,6690,0.155,1.77,,
1.79,6720,0.155,1.77,,
1.79,6740,0.156,1.78,,
1.79,6770,0.156,1.78,,
1.8,6790,0.157,1.79,,
1.8,6820,0.158,1.79,,
1.81,6840,0.158,1.8,,
1.81,6860,0.159,1.8,,
1.82,6890,0.16,1.81,,
1.82,6910,0.16,1.81,,
1.83,6940,0.161,1.81,,
1.83,6960,0.161,1.82,,
1.83,6990,0.162,1.82,,
1.84,7010,0.162,1.83,,
1.84,7030,0.163,1.83,,
1.85,7060,0.164,1.84,,
1.85,7080,0.164,1.84,,
1.86,7110,0.165,1.85,,
1.86,7130,0.166,1.85,,
1.87,7160,0.166,1.85,,
1.87,7180,0.167,1.86,,
1.88,7210,0.167,1.86,,
1.88,7230,0.168,1.87,,
1.88,7260,0.169,1.87,,
1.89,7280,0.169,1.88,,
1.89,7310,0.17,1.88,,
1.9,7330,0.17,1.89,,
1.9,7350,0.171,1.89,,
1.91,7380,0.172,1.89,,
1.91,7400,0.172,1.9,,
1.92,7430,0.173,1.9,,
1.92,7450,0.174,1.91,,
1.92,7480,0.174,1.91,,
1.93,7500,0.175,1.92,,
1.93,7530,0.176,1.92,,
1.94,7550,0.176,1.93,,
1.94,7580,0.177,1.93,,
1.95,7600,0.177,1.94,,
1.95,7630,0.178,1.94,,
1.96,7650,0.179,1.94,,
1.96,7680,0.179,1.95,,
1.96,7700,0.18,1.95,,
1.97,7730,0.181,1.96,,
1.97,7750,0.181,1.96,,
1.98,7780,0.182,1.97,,
1.98,7800,0.182,1.97,,
1.99,7830,0.183,1.98,,
1.99,7850,0.184,1.98,,
2,7880,0.184,1.98,,
2,7900,0.185,1.99,,
2,7930,0.186,1.99,,
2.01,7950,0.186,2,,
2.01,7980,0.187,2,,
2.02,8000,0.187,2.01,,
2.02,8030,0.188,2.01,,
2.03,8050,0.189,2.02,,
2.03,8080,0.189,2.02,,
2.04,8100,0.19,2.02,,
2.04,8130,0.191,2.03,,
2.05,8160,0.191,2.03,,
2.05,8180,0.192,2.04,,
2.05,8200,0.192,2.04,,
2.06,8230,0.193,2.05,,
2.06,8260,0.194,2.05,,
2.07,8280,0.194,2.06,,
2.07,8310,0.195,2.06,,
2.08,8330,0.196,2.06,,
2.08,8360,0.196,2.07,,
2.09,8380,0.197,2.07,,
2.09,8410,0.198,2.08,,
2.09,8440,0.198,2.08,,
2.1,8460,0.199,2.09,,
2.1,8490,0.199,2.09,,
2.11,8510,0.2,2.1,,
2.11,8540,0.201,2.1,,
2.12,8570,0.201,2.11,,
2.12,8590,0.202,2.11,,
2.13,8620,0.203,2.11,,
2.13,8640,0.203,2.12,,
2.13,8670,0.204,2.12,,
2.14,8700,0.205,2.13,,
2.14,8720,0.205,2.13,,
2.15,8750,0.206,2.14,,
2.15,8770,0.207,2.14,,
2.16,8800,0.207,2.15,,
2.16,8830,0.208,2.15,,
2.17,8850,0.209,2.15,,
2.17,8880,0.209,2.16,,
2.17,8900,0.21,2.16,,
2.18,8930,0.211,2.17,,
2.18,8960,0.211,2.17,,
2.19,8980,0.212,2.18,,
2.19,9010,0.213,2.18,,
2.2,9040,0.213,2.19,,
2.2,9060,0.214,2.19,,
2.21,9090,0.215,2.19,,
2.21,9120,0.215,2.2,,
2.22,9140,0.216,2.2,,
2.22,9170,0.217,2.21,,
2.22,9200,0.217,2.21,,
2.23,9220,0.218,2.22,,
2.23,9250,0.219,2.22,,
2.24,9270,0.219,2.23,,
2.24,9300,0.22,2.23,,
2.25,9330,0.221,2.23,,
2.25,9350,0.221,2.24,,
2.26,9380,0.222,2.24,,
2.26,9410,0.223,2.25,,
2.26,9430,0.223,2.25,,
2.27,9460,0.224,2.26,,
2.27,9490,0.225,2.26,,
2.28,9510,0.225,2.27,,
2.28,9540,0.226,2.27,,
2.29,9570,0.227,2.28,,
2.29,9600,0.227,2.28,,
2.3,9620,0.228,2.28,,
2.3,9650,0.229,2.29,,
2.3,9680,0.229,2.29,,
2.31,9700,0.23,2.3,,
2.31,9730,0.231,2.3,,
2.32,9760,0.231,2.31,,
2.32,9780,0.232,2.31,,
2.33,9810,0.233,2.32,,
2.33,9840,0.234,2.32,,
2.34,9870,0.234,2.32,,
2.34,9890,0.235,2.33,,
2.35,9920,0.236,2.33,,
2.35,9950,0.236,2.34,,
2.35,9970,0.237,2.34,,
2.36,10000,0.238,2.35,,
2.36,10000,0.238,2.35,,
2.37,10100,0.239,2.36,,
2.37,10100,0.24,2.36,,
2.38,10100,0.241,2.36,,
2.38,10100,0.241,2.37,,
2.39,10200,0.242,2.37,,
2.39,10200,0.243,2.38,,
2.39,10200,0.243,2.38,,
2.4,10200,0.244,2.39,,
2.4,10300,0.245,2.39,,
2.41,10300,0.245,2.4,,
2.41,10300,0.246,2.4,,
2.42,10400,0.247,2.41,,
2.42,10400,0.247,2.41,,
2.43,10400,0.248,2.41,,
2.43,10400,0.249,2.42,,
2.43,10500,0.25,2.42,,
2.44,10500,0.25,2.43,,
2.44,10500,0.251,2.43,,
2.45,10500,0.252,2.44,,
2.45,10600,0.252,2.44,,
2.46,10600,0.253,2.45,,
2.46,10600,0.254,2.45,,
2.47,10700,0.254,2.45,,
2.47,10700,0.255,2.46,,
2.47,10700,0.256,2.46,,
2.48,10700,0.257,2.47,,
2.48,10800,0.257,2.47,,
2.49,10800,0.258,2.48,,
2.49,10800,0.259,2.48,,
2.5,10800,0.259,2.49,,
2.5,10900,0.26,2.49,,
2.51,10900,0.261,2.49,,
2.51,10900,0.262,2.5,,
2.52,11000,0.262,2.5,,
2.52,11000,0.263,2.51,,
2.52,11000,0.264,2.51,,
2.53,11000,0.264,2.52,,
2.53,11100,0.265,2.52,,
2.54,11100,0.266,2.53,,
2.54,11100,0.266,2.53,,
2.55,11200,0.267,2.53,,
2.55,11200,0.268,2.54,,
2.56,11200,0.269,2.54,,
2.56,11200,0.269,2.55,,
2.56,11300,0.27,2.55,,
2.57,11300,0.271,2.56,,
2.57,11300,0.272,2.56,,
2.58,11300,0.272,2.57,,
2.58,11400,0.273,2.57,,
2.59,11400,0.274,2.58,,
2.59,11400,0.275,2.58,,
2.6,11500,0.275,2.58,,
2.6,11500,0.276,2.59,,
2.6,11500,0.277,2.59,,
2.61,11500,0.277,2.6,,
2.61,11600,0.278,2.6,,
2.62,11600,0.279,2.61,,
2.62,11600,0.28,2.61,,
2.63,11700,0.28,2.62,,
2.63,11700,0.281,2.62,,
2.64,11700,0.282,2.62,,
2.64,11700,0.282,2.63,,
2.64,11800,0.283,2.63,,
2.65,11800,0.284,2.64,,
2.65,11800,0.285,2.64,,
2.66,11900,0.285,2.65,,
2.66,11900,0.286,2.65,,
2.67,11900,0.287,2.66,,
2.67,11900,0.288,2.66,,
2.68,12000,0.288,2.66,,
2.68,12000,0.289,2.67,,
2.69,12000,0.29,2.67,,
2.69,12100,0.291,2.68,,
2.69,12100,0.291,2.68,,
2.7,12100,0.292,2.69,,
2.7,12100,0.293,2.69,,
2.71,12200,0.294,2.7,,
2.71,12200,0.294,2.7,,
2.72,12200,0.295,2.71,,
2.72,12200,0.296,2.71,,
2.73,12300,0.297,2.71,,
2.73,12300,0.297,2.72,,
2.73,12300,0.298,2.72,,
2.74,12400,0.299,2.73,,
2.74,12400,0.299,2.73,,
2.75,12400,0.3,2.74,,
2.75,12400,0.301,2.74,,
2.76,12500,0.302,2.75,,
2.76,12500,0.303,2.75,,
2.77,12500,0.303,2.75,,
2.77,12600,0.304,2.76,,
2.77,12600,0.305,2.76,,
2.78,12600,0.306,2.77,,
2.78,12600,0.306,2.77,,
2.79,12700,0.307,2.78,,
2.79,12700,0.308,2.78,,
2.8,12700,0.308,2.79,,
2.8,12800,0.309,2.79,,
2.81,12800,0.31,2.79,,
2.81,12800,0.311,2.8,,
2.82,12800,0.312,2.8,,
2.82,12900,0.312,2.81,,
2.82,12900,0.313,2.81,,
2.83,12900,0.314,2.82,,
2.83,13000,0.315,2.82,,
2.84,13000,0.315,2.83,,
2.84,13000,0.316,2.83,,
2.85,13000,0.317,2.83,,
2.85,13100,0.318,2.84,,
2.86,13100,0.318,2.84,,
2.86,13100,0.319,2.85,,
2.86,13200,0.32,2.85,,
2.87,13200,0.321,2.86,,
2.87,13200,0.321,2.86,,
2.88,13200,0.322,2.87,,
2.88,13300,0.323,2.87,,
2.89,13300,0.324,2.88,,
2.89,13300,0.324,2.88,,
2.9,13400,0.325,2.88,,
2.9,13400,0.326,2.89,,
2.9,13400,0.327,2.89,,
2.91,13400,0.327,2.9,,
2.91,13500,0.328,2.9,,
2.92,13500,0.329,2.91,,
2.92,13500,0.33,2.91,,
2.93,13600,0.331,2.92,,
2.93,13600,0.331,2.92,,
2.94,13600,0.332,2.92,,
2.94,13600,0.333,2.93,,
2.94,13700,0.334,2.93,,
2.95,13700,0.334,2.94,,
2.95,13700,0.335,2.94,,
2.96,13800,0.336,2.95,,
2.96,13800,0.337,2.95,,
2.97,13800,0.338,2.96,,
2.97,13800,0.338,2.96,,
2.98,13900,0.339,2.96,,
2.98,13900,0.34,2.97,,
2.99,13900,0.341,2.97,,
2.99,14000,0.341,2.98,,
2.99,14000,0.342,2.98,,
3,14000,0.343,2.99,,
3,14000,0.344,2.99,,
3.01,14100,0.345,3,,
3.01,14100,0.345,3,,
3.02,14100,0.346,3.01,,
3.02,14200,0.347,3.01,,
3.03,14200,0.348,3.01,,
3.03,14200,0.349,3.02,,
3.03,14200,0.349,3.02,,
3.04,14300,0.35,3.03,,
3.04,14300,0.351,3.03,,
3.05,14300,0.352,3.04,,
3.05,14400,0.352,3.04,,
3.06,14400,0.353,3.05,,
3.06,14400,0.354,3.05,,
3.07,14400,0.355,3.05,,
3.07,14500,0.356,3.06,,
3.07,14500,0.356,3.06,,
3.08,14500,0.357,3.07,,
3.08,14600,0.358,3.07,,
3.09,14600,0.359,3.08,,
3.09,14600,0.36,3.08,,
3.1,14700,0.361,3.09,,
3.1,14700,0.361,3.09,,
3.11,14700,0.362,3.09,,
3.11,14700,0.363,3.1,,
3.11,14800,0.364,3.1,,
3.12,14800,0.365,3.11,,
3.12,14800,0.366,3.11,,
3.13,14900,0.366,3.12,,
3.13,14900,0.367,3.12,,
3.14,14900,0.368,3.13,,
3.14,14900,0.369,3.13,,
3.15,15000,0.37,3.13,,
3.15,15000,0.37,3.14,,
3.16,15000,0.371,3.14,,
3.16,15100,0.372,3.15,,
3.16,15100,0.373,3.15,,
3.17,15100,0.374,3.16,,
3.17,15100,0.375,3.16,,
3.18,15200,0.375,3.17,,
3.18,15200,0.376,3.17,,
3.19,15200,0.377,3.18,,
3.19,15300,0.378,3.18,,
3.2,15300,0.379,3.18,,
3.2,15300,0.38,3.19,,
3.2,15300,0.381,3.19,,
3.21,15400,0.381,3.2,,
3.21,15400,0.382,3.2,,
3.22,15400,0.383,3.21,,
3.22,15500,0.384,3.21,,
3.23,15500,0.385,3.22,,
3.23,15500,0.386,3.22,,
3.24,15500,0.387,3.22,,
3.24,15600,0.388,3.23,,
3.25,15600,0.389,3.23,,
3.25,15600,0.389,3.24,,
3.25,15700,0.39,3.24,,
3.26,15700,0.391,3.25,,
3.26,15700,0.392,3.25,,
3.27,15800,0.393,3.26,,
3.27,15800,0.394,3.26,,
3.28,15800,0.395,3.26,,
3.28,15800,0.396,3.27,,
3.29,15900,0.397,3.27,,
3.29,15900,0.398,3.28,,
3.29,15900,0.399,3.28,,
3.3,16000,0.4,3.29,,
3.3,16000,0.4,3.29,,
3.31,16000,0.401,3.3,,
3.31,16000,0.403,3.3,,
3.32,16100,0.403,3.3,,
3.32,16100,0.404,3.31,,
3.33,16100,0.405,3.31,,
3.33,16200,0.406,3.32,,
3.33,16200,0.407,3.32,,
3.34,16200,0.408,3.33,,
3.34,16200,0.409,3.33,,
3.35,16300,0.41,3.34,,
3.35,16300,0.411,3.34,,
3.36,16300,0.412,3.35,,
3.36,16400,0.414,3.35,,
3.37,16400,0.415,3.35,,
3.37,16400,0.416,3.36,,
3.37,16400,0.417,3.36,,
3.38,16500,0.418,3.37,,
3.38,16500,0.419,3.37,,
3.39,16500,0.42,3.38,,
3.39,16600,0.421,3.38,,
3.4,16600,0.423,3.39,,
3.4,16600,0.424,3.39,,
3.41,16600,0.425,3.39,,
3.41,16700,0.426,3.4,,
3.42,16700,0.427,3.4,,
3.42,16700,0.428,3.41,,
3.42,16700,0.43,3.41,,
3.43,16800,0.431,3.42,,
3.43,16800,0.432,3.42,,
3.44,16800,0.434,3.43,,
3.44,16900,0.435,3.43,,
3.45,16900,0.436,3.43,,
3.45,16900,0.438,3.44,,
3.46,16900,0.439,3.44,,
3.46,17000,0.441,3.45,,
3.46,17000,0.442,3.45,,
3.47,17000,0.444,3.46,,
3.47,17000,0.445,3.46,,
3.48,17100,0.447,3.47,,
3.48,17100,0.449,3.47,,
3.49,17100,0.45,3.48,,
3.49,17100,0.452,3.48,,
3.5,17200,0.454,3.48,,
3.5,17200,0.456,3.49,,
3.5,17200,0.458,3.49,,
3.51,17200,0.46,3.5,,
3.51,17300,0.462,3.5,,
3.52,17300,0.464,3.51,,
3.52,17300,0.467,3.51,,
3.53,17300,0.469,3.52,,
3.53,17400,0.472,3.52,,
3.54,17400,0.474,3.52,,
3.54,17400,0.477,3.53,,
3.54,17400,0.48,3.53,,
3.55,17400,0.483,3.54,,
3.55,17400,0.487,3.54,,
3.56,17500,0.49,3.55,,
3.56,17500,0.494,3.55,,
3.57,17500,0.498,3.56,,
3.57,17500,0.502,3.56,,
3.58,17500,0.507,3.56,,
3.58,17500,0.511,3.57,,
3.58,17500,0.516,3.57,,
3.59,17500,0.521,3.58,,
3.59,17500,0.526,3.58,,
3.6,17500,0.532,3.59,,
3.6,17500,0.538,3.59,,
3.61,17500,0.543,3.6,,
3.61,17600,0.549,3.6,,
3.62,17600,0.555,3.6,,
3.62,17600,0.562,3.61,,
3.63,17600,0.568,3.61,,
3.63,17600,0.575,3.62,,
3.63,17600,0.581,3.62,,
3.64,17600,0.588,3.63,,
3.64,17600,0.595,3.63,,
3.65,17600,0.601,3.64,,
3.65,17600,0.608,3.64,,
3.66,17600,0.615,3.65,,
3.66,17600,0.622,3.65,,
3.67,17600,0.629,3.65,,
3.67,17500,0.636,3.66,,
3.67,17500,0.643,3.66,,
3.68,17500,0.65,3.67,,
3.68,17500,0.657,3.67,,
3.69,17500,0.665,3.68,,
3.69,17500,0.672,3.68,,
3.7,17500,0.679,3.69,,
3.7,17500,0.686,3.69,,
3.71,17500,0.693,3.69,,
3.71,17500,0.699,3.7,,
3.72,17500,0.706,3.7,,
3.72,17500,0.713,3.71,,
3.72,17500,0.72,3.71,,
3.73,17500,0.728,3.72,,
3.73,17500,0.735,3.72,,
3.74,17500,0.742,3.73,,
3.74,17500,0.749,3.73,,
3.75,17500,0.757,3.73,,
3.75,17500,0.764,3.74,,
3.76,17500,0.771,3.74,,
3.76,17500,0.779,3.75,,
3.76,17500,0.786,3.75,,
3.77,17500,0.801,3.76,,
3.77,17500,0.801,3.76,,
3.78,17500,0.808,3.77,,
3.78,17500,0.816,3.77,,
3.79,17500,0.823,3.78,,
3.79,17500,0.83,3.78,,
3.8,17500,0.838,3.78,,
3.8,17500,0.845,3.79,,
3.8,17500,0.853,3.79,,
3.81,17500,0.86,3.8,,
3.81,17500,0.868,3.8,,
3.82,17500,0.875,3.81,,
3.82,17500,0.882,3.81,,
3.83,17500,0.89,3.82,,
3.83,17500,0.897,3.82,,
3.84,17500,0.905,3.82,,
3.84,17500,0.905,3.83,,
3.84,17500,0.91,3.83,,
3.85,17500,0.927,3.84,,
3.85,17500,0.931,3.84,,
3.86,17500,0.941,3.85,,
3.86,17500,0.945,3.85,,
3.87,17500,0.958,3.86,,
3.87,17500,0.966,3.86,,
3.88,17500,0.974,3.86,,
3.88,17500,0.981,3.87,,
3.89,17500,0.989,3.87,,
3.89,17500,0.997,3.88,,
3.89,17500,1,3.88,,
3.9,17500,1.02,3.89,,
3.9,17500,1.03,3.89,,
3.91,17500,1.03,3.9,,
3.91,17500,1.01,3.9,,
3.92,17500,0.792,3.9,,
3.92,17500,0.112,3.91,,
3.93,17500,-1.69,3.91,,
3.93,17500,-2.28,3.92,,
3.93,17500,-1.04,3.92,,
3.94,17500,-1,3.93,,
3.94,17500,-1.39,3.93,,
3.95,17600,-7.63,3.94,,
3.95,17600,-7.58,3.94,,
3.96,17600,-7.57,3.95,,
3.96,17600,-7.57,3.95,,
3.97,17600,-7.57,3.95,,
3.97,17600,-7.57,3.96,,
3.97,17600,-7.57,3.96,,
3.98,17600,-7.57,3.97,,
3.98,17600,-7.57,3.97,,
3.99,17600,-7.57,3.98,,
3.99,17600,-7.57,3.98,,
4,17600,-7.57,3.99,,
4,17600,-7.57,3.99,,
4.01,17600,-7.57,3.99,,
4.01,17600,-7.57,4,,
4.01,17600,-7.57,4,,
4.02,17600,-7.57,4.01,,
4.02,17600,-7.57,4.01,,
4.03,17600,-7.57,4.02,,
4.03,17600,-7.57,4.02,,
4.04,17600,-7.57,4.03,,
4.04,17600,-7.57,4.03,,
4.05,17600,-7.57,4.03,,
4.05,17600,-7.57,4.04,,
4.06,17600,-7.57,4.04,,
4.06,17600,-7.57,4.05,,
4.06,17600,-7.57,4.05,,
4.07,17600,-7.57,4.06,,
4.07,17600,-7.56,4.06,,
4.08,17600,-7.55,4.07,,
4.08,17600,-7.57,4.07,,
4.09,17600,-7.6,4.08,,
4.09,17600,-7.61,4.08,,
4.1,17600,-7.61,4.08,,
4.1,17600,-7.64,4.09,,
4.1,17600,-7.61,4.09,,
4.11,17600,-7.6,4.1,,
4.11,17600,-7.26,4.1,,
4.12,17600,-3.07,4.11,,
4.12,17600,-4.2,4.11,,
4.13,17600,-7.6,4.12,,
4.13,17600,-6.33,4.12,,
4.14,17600,-0.714,4.12,,
4.14,17600,-0.413,4.13,,
4.14,17600,-0.343,4.13,,
4.15,17600,-0.163,4.14,,
4.15,17600,-0.176,4.14,,
4.16,17600,-0.148,4.15,,
4.16,17600,0.00414,4.15,,
4.17,17600,0.0673,4.16,,
4.17,17600,0.165,4.16,,
4.18,17600,0.43,4.16,,
4.18,17600,-0.0481,4.17,,
4.19,17600,-0.233,4.17,,
4.19,17600,0.408,4.18,,
4.19,17600,0.0312,4.18,,
4.2,17700,0.038,4.19,,
4.2,17700,0.05,4.19,,
4.21,17700,0.0509,4.2,,
4.21,17700,0.0746,4.2,,
4.22,17700,0.0966,4.2,,
4.22,17700,0.104,4.21,,
4.23,17700,0.125,4.21,,
4.23,17700,0.112,4.22,,
4.23,17700,0.0996,4.22,,
4.24,17700,0.104,4.23,,
4.24,17700,0.104,4.23,,
4.25,17700,0.117,4.24,,
4.25,17700,0.11,4.24,,
4.26,17700,0.112,4.25,,
4.27,17700,0.111,4.25,,
4.27,17700,0.111,4.25,,
4.36,18100,0.11,4.26,,
4.5,18100,0.108,4.26,,
4.64,18200,0.109,4.27,,
4.77,18200,0.108,4.27,,
4.91,18300,0.105,4.28,,
5.05,18400,0.1,4.28,,
5.18,18400,0.0992,4.29,,
5.32,18500,0.102,4.29,,
5.45,18600,0.0918,4.3,,
5.59,18600,0.0979,4.3,,
5.73,18700,0.172,4.3,,
5.86,18700,0.143,4.31,,
6,18700,0.175,4.31,,
6.14,18800,0.153,4.32,,
6.27,18800,0.229,4.32,,
6.41,18800,0.231,4.33,,
6.54,18800,0.246,4.33,,
6.68,18900,0.176,4.34,,
6.82,18900,0.153,4.34,,
6.95,18900,0.144,4.35,,
7.09,18900,0.141,4.35,,
7.23,18900,0.142,4.35,,
7.36,18900,0.139,4.36,,
7.5,18900,0.139,4.36,,
7.63,18800,0.139,4.37,,
7.77,18800,0.138,4.37,,
7.91,18800,0.137,4.38,,
8.04,18700,0.138,4.38,,
8.18,18700,0.138,4.39,,
8.31,18600,0.139,4.39,,
8.45,18500,0.139,4.39,,
8.59,18300,0.138,4.4,,
8.72,18000,0.139,4.4,,
8.86,17800,0.138,4.41,,
9,17500,0.138,4.41,,
9.13,17200,0.138,4.42,,
9.27,16900,0.134,4.42,,
9.4,16600,0.132,4.43,,
9.54,16300,0.157,4.43,,
9.68,16000,0.13,4.44,,
9.81,15700,0.131,4.44,,
9.95,15300,0.153,4.44,,
10.1,15000,0.124,4.45,,
10.2,14600,0.129,4.45,,
10.4,14200,0.117,4.46,,
10.5,13800,0.115,4.46,,
10.6,13400,0.128,4.47,,
10.8,13000,0.136,4.47,,
11,370,0.137,4.48,,