File: Job Rotation 1/MR02.csv
Position (mm);Force (N);Strain (%);Time (min)
0.00;1.67;0.000167;0.00405
0.0130;61.7;0.00150;0.00664
0.0257;41.7;0.000667;0.0116
0.0310;40.5;0.000500;0.0165
0.0360;41.7;0.000333;0.0214
0.0410;40.0;0.000228;0.0263
0.0460;40.0;0.000167;0.0313
0.0510;38.3;0.00;0.0362
0.0560;38.3;-0.000167;0.0411
0.0610;36.7;-0.000167;0.0461
0.0660;36.7;-0.000333;0.0510
0.0702;35.0;-0.000500;0.0559
0.0752;35.0;-0.000500;0.0608
0.0801;35.0;-0.000667;0.0658
0.0851;33.3;-0.000667;0.0707
0.0900;33.3;-0.000833;0.0756
0.0950;33.3;-0.000833;0.0806
0.100;33.3;-0.000833;0.0855
0.105;33.3;-0.000833;0.0904
0.110;33.3;-0.00100;0.0953
0.115;35.0;-0.00100;0.100
0.120;65.0;-0.000333;0.105
0.125;75.0;-4.84E-05;0.110
0.130;79.5;0.00;0.115
0.134;81.7;0.000167;0.120
0.140;85.0;0.000500;0.125
0.145;83.3;0.000667;0.130
0.149;85.0;0.000833;0.135
0.154;86.7;0.00117;0.140
0.159;90.0;0.00133;0.145
0.164;93.3;0.00167;0.150
0.169;117;0.00233;0.154
0.174;130;0.00287;0.159
0.179;140;0.00333;0.164
0.184;147;0.00367;0.169
0.189;155;0.00383;0.174
0.194;163;0.00417;0.179
0.199;170;0.00433;0.184
0.203;177;0.00450;0.189
0.209;183;0.00467;0.194
0.214;190;0.00483;0.199
0.218;195;0.00500;0.204
0.223;200;0.00517;0.209
0.228;205;0.00533;0.214
0.233;210;0.00550;0.219
0.238;215;0.00550;0.223
0.243;220;0.00567;0.228
0.248;225;0.00567;0.233
0.253;232;0.00583;0.238
0.258;238;0.00600;0.243
0.262;243;0.00610;0.248
0.267;252;0.00617;0.253
0.272;258;0.00633;0.258
0.277;265;0.00650;0.263
0.282;272;0.00667;0.268
0.287;280;0.00683;0.273
0.292;287;0.00700;0.278
0.297;295;0.00717;0.283
0.302;302;0.00733;0.288
0.307;310;0.00750;0.292
0.312;317;0.00767;0.297
0.317;325;0.00783;0.302
0.322;333;0.00800;0.307
0.327;340;0.00833;0.312
0.332;348;0.00847;0.317
0.337;356;0.00867;0.322
0.342;363;0.00883;0.327
0.347;371;0.00900;0.332
0.352;378;0.00927;0.337
0.356;384;0.00933;0.342
0.361;393;0.00950;0.347
0.366;402;0.00973;0.352
0.371;408;0.0100;0.357
0.376;417;0.0102;0.361
0.381;425;0.0103;0.366
0.386;433;0.0107;0.371
0.391;440;0.0108;0.376
0.396;448;0.0110;0.381
0.401;455;0.0113;0.386
0.406;463;0.0115;0.391
0.411;472;0.0118;0.396
0.415;480;0.0120;0.401
0.420;488;0.0123;0.406
0.425;497;0.0125;0.411
0.430;505;0.0127;0.416
0.435;514;0.0130;0.421
0.440;522;0.0132;0.426
0.445;530;0.0135;0.430
0.450;538;0.0137;0.435
0.455;547;0.0140;0.440
0.460;555;0.0142;0.445
0.465;563;0.0145;0.450
0.470;572;0.0147;0.455
0.475;581;0.0148;0.460
0.479;590;0.0152;0.465
0.484;598;0.0153;0.470
0.489;607;0.0155;0.475
0.494;617;0.0158;0.480
0.499;626;0.0161;0.485
0.504;635;0.0163;0.490
0.509;643;0.0165;0.495
0.514;653;0.0167;0.499
0.519;663;0.0170;0.504
0.524;672;0.0172;0.509
0.529;682;0.0173;0.514
0.534;690;0.0177;0.519
0.539;700;0.0178;0.524
0.544;710;0.0182;0.529
0.549;718;0.0183;0.534
0.554;728;0.0185;0.539
0.558;738;0.0188;0.544
0.563;748;0.0191;0.549
0.568;758;0.0193;0.554
0.573;768;0.0195;0.559
0.578;778;0.0198;0.564
0.583;788;0.0200;0.568
0.588;798;0.0203;0.573
0.593;808;0.0205;0.578
0.598;818;0.0208;0.583
0.603;828;0.0210;0.588
0.608;839;0.0213;0.593
0.613;849;0.0215;0.598
0.617;859;0.0218;0.603
0.622;870;0.0220;0.608
0.627;880;0.0223;0.613
0.632;891;0.0227;0.618
0.637;900;0.0228;0.623
0.642;912;0.0232;0.628
0.647;923;0.0233;0.633
0.652;933;0.0237;0.637
0.657;943;0.0240;0.642
0.662;953;0.0242;0.647
0.667;965;0.0245;0.652
0.672;977;0.0248;0.657
0.677;987;0.0252;0.662
0.682;998;0.0253;0.667
0.687;1010;0.0257;0.672
0.692;1020;0.0260;0.677
0.697;1030;0.0262;0.682
0.701;1040;0.0265;0.687
0.706;1050;0.0268;0.692
0.711;1070;0.0272;0.697
0.716;1080;0.0274;0.702
0.721;1090;0.0277;0.706
0.726;1100;0.0280;0.711
0.731;1110;0.0283;0.716
0.736;1120;0.0287;0.721
0.741;1130;0.0288;0.726
0.746;1140;0.0292;0.731
0.751;1160;0.0295;0.736
0.756;1170;0.0298;0.741
0.761;1180;0.0302;0.746
0.765;1190;0.0305;0.751
0.770;1200;0.0308;0.756
0.775;1220;0.0311;0.761
0.780;1230;0.0315;0.766
0.785;1240;0.0317;0.771
0.790;1250;0.0320;0.775
0.795;1260;0.0323;0.780
0.800;1280;0.0327;0.785
0.805;1290;0.0330;0.790
0.810;1300;0.0333;0.795
0.815;1310;0.0337;0.800
0.820;1330;0.0340;0.805
0.825;1340;0.0344;0.810
0.829;1350;0.0347;0.815
0.834;1370;0.0352;0.820
0.839;1380;0.0355;0.825
0.844;1390;0.0357;0.830
0.849;1400;0.0362;0.835
0.854;1420;0.0365;0.840
0.859;1430;0.0367;0.844
0.864;1440;0.0372;0.849
0.869;1460;0.0375;0.854
0.874;1470;0.0378;0.859
0.879;1480;0.0382;0.864
0.884;1490;0.0385;0.869
0.889;1510;0.0388;0.874
0.894;1520;0.0393;0.879
0.898;1530;0.0397;0.884
0.904;1550;0.0400;0.889
0.908;1560;0.0403;0.894
0.913;1580;0.0407;0.899
0.918;1590;0.0411;0.904
0.923;1600;0.0415;0.909
0.928;1610;0.0418;0.913
0.933;1630;0.0422;0.918
0.938;1640;0.0426;0.923
0.943;1650;0.0430;0.928
0.948;1670;0.0433;0.933
0.953;1680;0.0437;0.938
0.958;1700;0.0442;0.943
0.963;1710;0.0445;0.948
0.967;1720;0.0448;0.953
0.972;1740;0.0453;0.958
0.977;1750;0.0457;0.963
0.982;1760;0.0460;0.968
0.987;1780;0.0465;0.973
0.992;1790;0.0468;0.978
0.997;1810;0.0472;0.982
1.00;1820;0.0477;0.987
1.01;1830;0.0480;0.992
1.01;1850;0.0483;0.997
1.02;1860;0.0488;1.00
1.02;1880;0.0492;1.01
1.03;1890;0.0497;1.01
1.03;1910;0.0500;1.02
1.04;1920;0.0503;1.02
1.04;1930;0.0508;1.03
1.05;1950;0.0512;1.03
1.05;1960;0.0516;1.04
1.06;1980;0.0520;1.04
1.06;1990;0.0523;1.05
1.07;2010;0.0528;1.05
1.07;2020;0.0533;1.06
1.08;2040;0.0537;1.06
1.08;2050;0.0540;1.07
1.09;2060;0.0545;1.07
1.09;2080;0.0548;1.08
1.10;2090;0.0553;1.08
1.10;2110;0.0557;1.09
1.11;2120;0.0562;1.09
1.11;2140;0.0567;1.10
1.12;2150;0.0570;1.10
1.12;2170;0.0574;1.11
1.13;2180;0.0578;1.11
1.13;2200;0.0583;1.12
1.14;2210;0.0587;1.12
1.14;2230;0.0592;1.13
1.15;2240;0.0595;1.13
1.15;2260;0.0600;1.14
1.16;2280;0.0603;1.14
1.16;2290;0.0608;1.15
1.16;2310;0.0612;1.15
1.17;2320;0.0615;1.15
1.17;2340;0.0620;1.16
1.18;2360;0.0625;1.16
1.18;2370;0.0628;1.17
1.19;2390;0.0632;1.17
1.19;2400;0.0637;1.18
1.20;2420;0.0640;1.18
1.20;2430;0.0645;1.19
1.21;2450;0.0648;1.19
1.21;2470;0.0653;1.20
1.22;2480;0.0657;1.20
1.22;2500;0.0662;1.21
1.23;2520;0.0665;1.21
1.23;2530;0.0670;1.22
1.24;2550;0.0673;1.22
1.24;2570;0.0678;1.23
1.25;2580;0.0683;1.23
1.25;2600;0.0687;1.24
1.26;2610;0.0691;1.24
1.26;2630;0.0695;1.25
1.27;2650;0.0700;1.25
1.27;2670;0.0704;1.26
1.28;2680;0.0708;1.26
1.28;2700;0.0712;1.27
1.29;2720;0.0717;1.27
1.29;2730;0.0722;1.28
1.30;2750;0.0725;1.28
1.30;2770;0.0730;1.29
1.31;2790;0.0735;1.29
1.31;2800;0.0740;1.30
1.32;2820;0.0743;1.30
1.32;2840;0.0748;1.31
1.33;2850;0.0753;1.31
1.33;2870;0.0757;1.32
1.34;2890;0.0762;1.32
1.34;2910;0.0765;1.33
1.35;2920;0.0770;1.33
1.35;2940;0.0775;1.34
1.36;2960;0.0780;1.34
1.36;2980;0.0784;1.35
1.37;3000;0.0788;1.35
1.37;3010;0.0793;1.36
1.38;3030;0.0798;1.36
1.38;3050;0.0803;1.37
1.39;3070;0.0807;1.37
1.39;3090;0.0812;1.38
1.40;3100;0.0816;1.38
1.40;3120;0.0820;1.39
1.41;3140;0.0825;1.39
1.41;3160;0.0830;1.40
1.42;3180;0.0835;1.40
1.42;3200;0.0840;1.41
1.43;3210;0.0845;1.41
1.43;3230;0.0848;1.42
1.44;3250;0.0853;1.42
1.44;3270;0.0858;1.43
1.45;3290;0.0863;1.43
1.45;3310;0.0868;1.44
1.46;3320;0.0872;1.44
1.46;3340;0.0877;1.45
1.47;3360;0.0882;1.45
1.47;3380;0.0887;1.46
1.48;3400;0.0892;1.46
1.48;3420;0.0896;1.47
1.49;3440;0.0902;1.47
1.49;3460;0.0906;1.48
1.50;3480;0.0910;1.48
1.50;3500;0.0915;1.49
1.51;3520;0.0920;1.49
1.51;3540;0.0925;1.50
1.52;3560;0.0930;1.50
1.52;3570;0.0935;1.50
1.52;3590;0.0940;1.51
1.53;3610;0.0945;1.51
1.53;3630;0.0950;1.52
1.54;3650;0.0955;1.52
1.54;3670;0.0960;1.53
1.55;3690;0.0965;1.53
1.55;3710;0.0970;1.54
1.56;3730;0.0975;1.54
1.56;3750;0.0980;1.55
1.57;3770;0.0985;1.55
1.57;3790;0.0990;1.56
1.58;3810;0.0995;1.56
1.58;3830;0.100;1.57
1.59;3850;0.101;1.57
1.59;3870;0.101;1.58
1.60;3890;0.101;1.58
1.60;3910;0.102;1.59
1.61;3930;0.102;1.59
1.61;3950;0.103;1.60
1.62;3970;0.104;1.60
1.62;3990;0.104;1.61
1.63;4010;0.105;1.61
1.63;4030;0.105;1.62
1.64;4050;0.105;1.62
1.64;4070;0.106;1.63
1.65;4090;0.106;1.63
1.65;4110;0.107;1.64
1.66;4130;0.108;1.64
1.66;4150;0.108;1.65
1.67;4170;0.109;1.65
1.67;4190;0.109;1.66
1.68;4220;0.110;1.66
1.68;4240;0.110;1.67
1.69;4260;0.111;1.67
1.69;4280;0.111;1.68
1.70;4300;0.112;1.68
1.70;4320;0.112;1.69
1.71;4340;0.113;1.69
1.71;4360;0.113;1.70
1.72;4380;0.114;1.70
1.72;4400;0.114;1.71
1.73;4430;0.115;1.71
1.73;4450;0.115;1.72
1.74;4470;0.116;1.72
1.74;4490;0.116;1.73
1.75;4510;0.117;1.73
1.75;4530;0.117;1.74
1.76;4560;0.118;1.74
1.76;4580;0.119;1.75
1.77;4600;0.119;1.75
1.77;4620;0.120;1.76
1.78;4640;0.120;1.76
1.78;4660;0.121;1.77
1.79;4680;0.121;1.77
1.79;4710;0.122;1.78
1.80;4730;0.122;1.78
1.80;4750;0.123;1.79
1.81;4770;0.123;1.79
1.81;4790;0.124;1.80
1.82;4820;0.125;1.80
1.82;4840;0.125;1.81
1.83;4860;0.126;1.81
1.83;4880;0.126;1.82
1.84;4910;0.127;1.82
1.84;4930;0.127;1.83
1.85;4950;0.128;1.83
1.85;4970;0.128;1.84
1.86;5000;0.129;1.84
1.86;5020;0.130;1.84
1.86;5040;0.130;1.85
1.87;5070;0.131;1.85
1.87;5090;0.131;1.86
1.88;5110;0.132;1.86
1.88;5130;0.132;1.87
1.89;5160;0.133;1.87
1.89;5180;0.134;1.88
1.90;5200;0.135;1.88
1.90;5230;0.135;1.89
1.91;5250;0.136;1.89
1.91;5270;0.136;1.90
1.92;5300;0.137;1.90
1.92;5320;0.138;1.91
1.93;5340;0.138;1.91
1.93;5370;0.139;1.92
1.94;5390;0.139;1.92
1.94;5410;0.140;1.93
1.95;5440;0.140;1.93
1.95;5460;0.141;1.94
1.96;5480;0.142;1.94
1.96;5510;0.142;1.95
1.97;5530;0.143;1.95
1.97;5560;0.144;1.96
1.98;5580;0.144;1.96
1.98;5610;0.145;1.97
1.99;5630;0.145;1.97
1.99;5650;0.146;1.98
2.00;5680;0.146;1.98
2.00;5700;0.147;1.99
2.01;5730;0.148;1.99
2.01;5750;0.148;2.00
2.02;5770;0.149;2.00
2.02;5800;0.149;2.01
2.03;5820;0.150;2.01
2.03;5850;0.151;2.02
2.04;5870;0.151;2.02
2.04;5890;0.152;2.03
2.05;5920;0.153;2.03
2.05;5940;0.153;2.04
2.06;5970;0.154;2.04
2.06;5990;0.154;2.05
2.07;6020;0.155;2.05
2.07;6040;0.155;2.06
2.08;6070;0.156;2.06
2.08;6090;0.157;2.07
2.09;6120;0.157;2.07
2.09;6140;0.158;2.08
2.10;6170;0.159;2.08
2.10;6190;0.159;2.09
2.11;6210;0.160;2.09
2.11;6240;0.161;2.10
2.12;6270;0.161;2.10
2.12;6290;0.162;2.11
2.13;6320;0.162;2.11
2.13;6340;0.163;2.12
2.14;6370;0.164;2.12
2.14;6390;0.164;2.13
2.15;6420;0.165;2.13
2.15;6440;0.166;2.14
2.16;6470;0.166;2.14
2.16;6490;0.167;2.15
2.17;6520;0.168;2.15
2.17;6540;0.168;2.16
2.18;6570;0.169;2.16
2.18;6590;0.169;2.17
2.19;6620;0.170;2.17
2.19;6650;0.171;2.18
2.20;6670;0.171;2.18
2.20;6700;0.172;2.19
2.21;6720;0.173;2.19
2.21;6750;0.173;2.19
2.21;6780;0.174;2.20
2.22;6800;0.175;2.20
2.22;6830;0.175;2.21
2.23;6850;0.176;2.21
2.23;6880;0.177;2.22
2.24;6910;0.177;2.22
2.24;6930;0.178;2.23
2.25;6960;0.178;2.23
2.25;6990;0.179;2.24
2.26;7010;0.180;2.24
2.26;7040;0.181;2.25
2.27;7060;0.181;2.25
2.27;7090;0.182;2.26
2.28;7120;0.183;2.26
2.28;7140;0.183;2.27
2.29;7170;0.184;2.27
2.29;7200;0.185;2.28
2.30;7220;0.185;2.28
2.30;7250;0.186;2.29
2.31;7280;0.187;2.29
2.31;7300;0.187;2.30
2.32;7330;0.188;2.30
2.32;7360;0.189;2.31
2.33;7380;0.189;2.31
2.33;7410;0.190;2.32
2.34;7440;0.191;2.32
2.34;7460;0.191;2.33
2.35;7490;0.192;2.33
2.35;7520;0.193;2.34
2.36;7550;0.193;2.34
2.36;7570;0.194;2.35
2.37;7600;0.195;2.35
2.37;7630;0.196;2.36
2.38;7650;0.196;2.36
2.38;7680;0.197;2.37
2.39;7710;0.198;2.37
2.39;7730;0.198;2.38
2.40;7760;0.199;2.38
2.40;7790;0.200;2.39
2.41;7820;0.200;2.39
2.41;7840;0.201;2.40
2.42;7870;0.202;2.40
2.42;7900;0.203;2.41
2.43;7930;0.203;2.41
2.43;7950;0.204;2.42
2.44;7980;0.205;2.42
2.44;8010;0.205;2.43
2.45;8030;0.206;2.43
2.45;8060;0.207;2.44
2.46;8090;0.207;2.44
2.46;8120;0.208;2.45
2.47;8140;0.209;2.45
2.47;8170;0.210;2.46
2.48;8200;0.210;2.46
2.48;8230;0.211;2.47
2.49;8250;0.212;2.47
2.49;8280;0.213;2.48
2.50;8310;0.213;2.48
2.50;8340;0.214;2.49
2.51;8370;0.215;2.49
2.51;8390;0.215;2.50
2.52;8420;0.216;2.50
2.52;8450;0.217;2.51
2.53;8480;0.218;2.51
2.53;8510;0.218;2.52
2.54;8540;0.219;2.52
2.54;8560;0.220;2.53
2.54;8590;0.220;2.53
2.55;8620;0.221;2.53
2.55;8650;0.222;2.54
2.56;8680;0.222;2.54
2.56;8700;0.223;2.55
2.57;8730;0.224;2.55
2.57;8760;0.225;2.56
2.58;8790;0.226;2.56
2.58;8820;0.226;2.57
2.59;8850;0.227;2.57
2.59;8870;0.228;2.58
2.60;8900;0.228;2.58
2.60;8930;0.229;2.59
2.61;8960;0.230;2.59
2.61;8990;0.231;2.60
2.62;9020;0.231;2.60
2.62;9050;0.232;2.61
2.63;9070;0.233;2.61
2.63;9100;0.234;2.62
2.64;9130;0.234;2.62
2.64;9160;0.235;2.63
2.65;9190;0.236;2.63
2.65;9220;0.237;2.64
2.66;9240;0.237;2.64
2.66;9270;0.238;2.65
2.67;9300;0.239;2.65
2.67;9330;0.240;2.66
2.68;9360;0.240;2.66
2.68;9390;0.241;2.67
2.69;9420;0.242;2.67
2.69;9450;0.243;2.68
2.70;9480;0.243;2.68
2.70;9510;0.244;2.69
2.71;9530;0.245;2.69
2.71;9570;0.246;2.70
2.72;9590;0.246;2.70
2.72;9620;0.247;2.71
2.73;9650;0.248;2.71
2.73;9680;0.249;2.72
2.74;9710;0.249;2.72
2.74;9740;0.250;2.73
2.75;9770;0.251;2.73
2.75;9800;0.252;2.74
2.76;9830;0.252;2.74
2.76;9860;0.253;2.75
2.77;9890;0.254;2.75
2.77;9910;0.255;2.76
2.78;9940;0.255;2.76
2.78;9970;0.256;2.77
2.79;10000;0.257;2.77
2.79;10000;0.258;2.78
2.80;10100;0.259;2.78
2.80;10100;0.259;2.79
2.81;10100;0.260;2.79
2.81;10200;0.261;2.80
2.82;10200;0.262;2.80
2.82;10200;0.262;2.81
2.83;10200;0.263;2.81
2.83;10300;0.264;2.82
2.84;10300;0.265;2.82
2.84;10300;0.266;2.83
2.85;10400;0.266;2.83
2.85;10400;0.267;2.84
2.86;10400;0.268;2.84
2.86;10500;0.269;2.85
2.87;10500;0.269;2.85
2.87;10500;0.270;2.86
2.88;10500;0.271;2.86
2.88;10600;0.272;2.87
2.88;10600;0.273;2.87
2.89;10600;0.273;2.88
2.89;10700;0.274;2.88
2.90;10700;0.275;2.88
2.90;10700;0.276;2.89
2.91;10700;0.276;2.89
2.91;10800;0.277;2.90
2.92;10800;0.278;2.90
2.92;10800;0.279;2.91
2.93;10900;0.280;2.91
2.93;10900;0.280;2.92
2.94;10900;0.281;2.92
2.94;11000;0.282;2.93
2.95;11000;0.283;2.93
2.95;11000;0.284;2.94
2.96;11100;0.285;2.94
2.96;11100;0.285;2.95
2.97;11100;0.286;2.95
2.97;11100;0.287;2.96
2.98;11200;0.288;2.96
2.98;11200;0.288;2.97
2.99;11200;0.289;2.97
2.99;11300;0.290;2.98
3.00;11300;0.291;2.98
3.00;11300;0.292;2.99
3.01;11400;0.292;2.99
3.01;11400;0.293;3.00
3.02;11400;0.294;3.00
3.02;11400;0.295;3.01
3.03;11500;0.296;3.01
3.03;11500;0.296;3.02
3.04;11500;0.297;3.02
3.04;11600;0.298;3.03
3.05;11600;0.299;3.03
3.05;11600;0.300;3.04
3.06;11700;0.301;3.04
3.06;11700;0.301;3.05
3.07;11700;0.302;3.05
3.07;11700;0.303;3.06
3.08;11800;0.304;3.06
3.08;11800;0.305;3.07
3.09;11800;0.305;3.07
3.09;11900;0.306;3.08
3.10;11900;0.307;3.08
3.10;11900;0.308;3.09
3.11;12000;0.309;3.09
3.11;12000;0.309;3.10
3.12;12000;0.310;3.10
3.12;12000;0.311;3.11
3.13;12100;0.312;3.11
3.13;12100;0.313;3.12
3.14;12100;0.313;3.12
3.14;12200;0.314;3.13
3.15;12200;0.315;3.13
3.15;12200;0.316;3.14
3.16;12300;0.317;3.14
3.16;12300;0.318;3.15
3.17;12300;0.319;3.15
3.17;12400;0.319;3.16
3.18;12400;0.320;3.16
3.18;12400;0.321;3.17
3.19;12400;0.322;3.17
3.19;12500;0.323;3.18
3.20;12500;0.323;3.18
3.20;12500;0.324;3.19
3.21;12600;0.325;3.19
3.21;12600;0.326;3.20
3.22;12600;0.327;3.20
3.22;12700;0.327;3.21
3.23;12700;0.328;3.21
3.23;12700;0.329;3.22
3.23;12800;0.330;3.22
3.24;12800;0.331;3.22
3.24;12800;0.332;3.23
3.25;12800;0.333;3.23
3.25;12900;0.333;3.24
3.26;12900;0.334;3.24
3.26;12900;0.335;3.25
3.27;13000;0.336;3.25
3.27;13000;0.337;3.26
3.28;13000;0.338;3.26
3.28;13100;0.339;3.27
3.29;13100;0.340;3.27
3.29;13100;0.340;3.28
3.30;13200;0.341;3.28
3.30;13200;0.342;3.29
3.31;13200;0.343;3.29
3.31;13300;0.344;3.30
3.32;13300;0.345;3.30
3.32;13300;0.345;3.31
3.33;13300;0.346;3.31
3.33;13400;0.347;3.32
3.34;13400;0.348;3.32
3.34;13400;0.349;3.33
3.35;13500;0.350;3.33
3.35;13500;0.351;3.34
3.36;13500;0.352;3.34
3.36;13600;0.352;3.35
3.37;13600;0.353;3.35
3.37;13600;0.354;3.36
3.38;13700;0.355;3.36
3.38;13700;0.356;3.37
3.39;13700;0.357;3.37
3.39;13800;0.358;3.38
3.40;13800;0.359;3.38
3.40;13800;0.359;3.39
3.41;13800;0.360;3.39
3.41;13900;0.361;3.40
3.42;13900;0.362;3.40
3.42;13900;0.363;3.41
3.43;14000;0.364;3.41
3.43;14000;0.365;3.42
3.44;14000;0.366;3.42
3.44;14100;0.366;3.43
3.45;14100;0.367;3.43
3.45;14100;0.368;3.44
3.46;14200;0.369;3.44
3.46;14200;0.370;3.45
3.47;14200;0.371;3.45
3.47;14300;0.372;3.46
3.48;14300;0.373;3.46
3.48;14300;0.374;3.47
3.49;14300;0.375;3.47
3.49;14400;0.375;3.48
3.50;14400;0.377;3.48
3.50;14400;0.377;3.49
3.51;14500;0.378;3.49
3.51;14500;0.379;3.50
3.52;14500;0.380;3.50
3.52;14600;0.381;3.51
3.53;14600;0.382;3.51
3.53;14600;0.383;3.52
3.54;14700;0.384;3.52
3.54;14700;0.385;3.53
3.55;14700;0.386;3.53
3.55;14800;0.387;3.54
3.56;14800;0.388;3.54
3.56;14800;0.389;3.55
3.57;14800;0.390;3.55
3.57;14900;0.391;3.56
3.57;14900;0.392;3.56
3.58;14900;0.393;3.57
3.58;15000;0.394;3.57
3.59;15000;0.395;3.57
3.59;15000;0.396;3.58
3.60;15100;0.397;3.58
3.60;15100;0.398;3.59
3.61;15100;0.399;3.59
3.61;15200;0.400;3.60
3.62;15200;0.401;3.60
3.62;15200;0.402;3.61
3.63;15300;0.403;3.61
3.63;15300;0.404;3.62
3.64;15300;0.405;3.62
3.64;15300;0.406;3.63
3.65;15400;0.407;3.63
3.65;15400;0.408;3.64
3.66;15400;0.409;3.64
3.66;15500;0.410;3.65
3.67;15500;0.411;3.65
3.67;15500;0.412;3.66
3.68;15600;0.413;3.66
3.68;15600;0.414;3.67
3.69;15600;0.415;3.67
3.69;15700;0.417;3.68
3.70;15700;0.418;3.68
3.70;15700;0.419;3.69
3.71;15800;0.420;3.69
3.71;15800;0.421;3.70
3.72;15800;0.422;3.70
3.72;15800;0.424;3.71
3.73;15900;0.425;3.71
3.73;15900;0.426;3.72
3.74;15900;0.427;3.72
3.74;16000;0.428;3.73
3.75;16000;0.430;3.73
3.75;16000;0.431;3.74
3.76;16100;0.432;3.74
3.76;16100;0.433;3.75
3.77;16100;0.435;3.75
3.77;16100;0.436;3.76
3.78;16200;0.438;3.76
3.78;16200;0.439;3.77
3.79;16200;0.440;3.77
3.79;16300;0.442;3.78
3.80;16300;0.443;3.78
3.80;16300;0.445;3.79
3.81;16400;0.446;3.79
3.81;16400;0.448;3.80
3.82;16400;0.449;3.80
3.82;16400;0.451;3.81
3.83;16500;0.453;3.81
3.83;16500;0.455;3.82
3.84;16500;0.456;3.82
3.84;16600;0.458;3.83
3.85;16600;0.460;3.83
3.85;16600;0.462;3.84
3.86;16600;0.464;3.84
3.86;16700;0.466;3.85
3.87;16700;0.469;3.85
3.87;16700;0.471;3.86
3.88;16700;0.473;3.86
3.88;16800;0.476;3.87
3.89;16800;0.479;3.87
3.89;16800;0.482;3.88
3.90;16800;0.485;3.88
3.90;16900;0.488;3.89
3.91;16900;0.491;3.89
3.91;16900;0.494;3.90
3.92;16900;0.498;3.90
3.92;16900;0.502;3.91
3.92;16900;0.506;3.91
3.93;17000;0.511;3.91
3.93;17000;0.515;3.92
3.94;17000;0.520;3.92
3.94;17000;0.525;3.93
3.95;17000;0.531;3.93
3.95;17000;0.537;3.94
3.96;17000;0.542;3.94
3.96;17000;0.549;3.95
3.97;17000;0.555;3.95
3.97;17000;0.562;3.96
3.98;17000;0.568;3.96
3.98;17000;0.575;3.97
3.99;17000;0.582;3.97
3.99;17000;0.589;3.98
4.00;17000;0.597;3.98
4.00;17000;0.604;3.99
4.01;17000;0.612;3.99
4.01;17000;0.619;4.00
4.02;17000;0.627;4.00
4.02;17000;0.634;4.01
4.03;17000;0.642;4.01
4.03;17000;0.650;4.02
4.04;17000;0.657;4.02
4.04;17000;0.665;4.03
4.05;17000;0.673;4.03
4.05;17000;0.681;4.04
4.06;17000;0.689;4.04
4.06;17000;0.697;4.05
4.07;17000;0.705;4.05
4.07;17000;0.713;4.06
4.08;17000;0.721;4.06
4.08;17000;0.729;4.07
4.09;17000;0.737;4.07
4.09;17000;0.745;4.08
4.10;17000;0.753;4.08
4.10;17000;0.761;4.09
4.11;17000;0.769;4.09
4.11;17000;0.777;4.10
4.12;17000;0.785;4.10
4.13;17000;0.802;4.11
4.13;17000;0.802;4.11
4.13;17000;0.810;4.12
4.14;17000;0.818;4.12
4.14;17000;0.826;4.13
4.15;17000;0.834;4.13
4.15;17000;0.842;4.14
4.16;17000;0.851;4.14
4.16;17000;0.858;4.15
4.17;17000;0.866;4.15
4.17;17000;0.874;4.16
4.18;17000;0.882;4.16
4.18;17000;0.890;4.17
4.19;17000;0.898;4.17
4.19;17000;0.907;4.18
4.20;17000;0.915;4.18
4.20;17000;0.923;4.19
4.21;17000;0.932;4.19
4.21;17000;0.940;4.20
4.22;17000;0.948;4.20
4.22;17000;0.957;4.21
4.23;17000;0.965;4.21
4.23;17000;0.973;4.22
4.24;17000;0.974;4.22
4.24;17000;0.998;4.23
4.25;17000;0.992;4.23
4.25;17000;0.999;4.24
4.25;17000;1.01;4.24
4.26;17000;1.02;4.24
4.26;17000;0.983;4.25
4.27;17000;-2.02;4.25
4.27;17000;-7.77;4.26
4.28;17000;-7.76;4.26
4.28;17000;-7.74;4.27
4.29;17000;-7.73;4.27
4.29;17000;-7.73;4.28
4.30;17000;-7.73;4.28
4.30;17000;-7.73;4.29
4.31;17000;-7.73;4.29
4.31;17000;-7.73;4.30
4.32;17000;-7.73;4.30
4.32;17000;-7.73;4.31
4.33;17000;-7.74;4.31
4.33;17000;-7.75;4.32
4.34;17100;-7.74;4.32
4.34;17100;-7.74;4.33
4.35;17100;-7.74;4.33
4.35;17100;-7.74;4.34
4.36;17100;-7.74;4.34
4.36;17100;-7.74;4.35
4.37;17100;-7.74;4.35
4.37;17100;-7.74;4.36
4.38;17100;-7.74;4.36
4.38;17100;-7.74;4.37
4.39;17100;-7.74;4.37
4.39;17100;-7.74;4.38
4.40;17100;-7.74;4.38
4.40;17100;-7.74;4.39
4.41;17100;-7.71;4.39
4.41;17100;-7.73;4.40
4.42;17100;-7.74;4.40
4.42;17100;-7.39;4.41
4.43;17100;-3.94;4.41
4.43;17100;-0.217;4.42
4.44;17100;-0.473;4.42
4.44;17100;-0.230;4.43
4.45;17100;-0.396;4.43
4.45;17100;-7.62;4.44
4.46;17100;-7.75;4.44
4.46;17100;-7.73;4.45
4.47;17100;-7.47;4.45
4.47;17100;-1.54;4.46
4.48;17100;0.0200;4.46
4.48;17100;-0.0402;4.47
4.49;17100;-0.0196;4.47
4.49;17100;0.0123;4.48
4.50;17100;0.0124;4.48
4.50;17100;0.0811;4.49
4.51;17100;0.134;4.49
4.51;17100;0.114;4.50
4.52;17100;0.0223;4.50
4.52;17100;0.00532;4.51
4.53;17100;0.0213;4.51
4.53;17100;0.0179;4.52
4.54;17100;0.0183;4.52
4.54;17100;0.0155;4.53
4.55;17100;0.0173;4.53
4.55;17100;0.0232;4.54
4.55;17100;0.00373;4.54
4.56;17100;0.00628;4.54
4.56;17100;0.00311;4.55
4.57;17200;0.0104;4.55
4.57;17200;0.0126;4.56
4.58;17200;0.0271;4.56
4.58;17200;0.0627;4.57
4.59;17200;0.0238;4.57
4.59;17200;0.0217;4.58
4.60;17200;0.00463;4.58
4.60;17200;0.0201;4.59
4.61;17200;0.0251;4.59
4.61;17200;0.0235;4.60
4.62;17200;0.0252;4.60
4.62;17200;0.0219;4.61
4.63;17200;0.0202;4.61
4.63;17200;0.0205;4.62
4.64;17200;0.0200;4.62
4.64;17200;0.0198;4.63
4.65;17200;0.0200;4.63
4.65;17200;0.0200;4.64
4.66;17200;0.0200;4.64
4.66;17200;0.0214;4.65
4.67;17200;0.0278;4.65
4.67;17200;0.0212;4.66
4.68;17200;0.0212;4.66
4.68;17200;0.0292;4.67
4.69;17200;0.0288;4.67
4.69;17200;0.0285;4.68
4.70;17200;0.0283;4.68
4.70;17200;0.0280;4.69
4.71;17200;0.0280;4.69
4.72;17200;0.0280;4.70
4.72;17200;0.0280;4.70
4.83;17600;0.0280;4.71
4.98;17600;0.0280;4.71
5.13;17700;0.0280;4.72
5.27;17800;0.0282;4.72
5.42;17900;0.0282;4.73
5.57;17900;0.0282;4.73
5.72;18000;0.0282;4.74
5.87;18100;0.0282;4.74
6.02;18100;0.0282;4.75
6.17;18200;0.0282;4.75
6.32;18200;0.0282;4.76
6.47;18300;0.0282;4.76
6.62;18300;0.0283;4.77
6.77;18300;0.0283;4.77
6.92;18300;0.0283;4.78
7.07;18300;0.0283;4.78
7.22;18400;0.0283;4.79
7.37;18400;0.0283;4.79
7.52;18400;0.0283;4.80
7.67;18300;0.0283;4.80
7.82;18300;0.0283;4.81
7.97;18300;0.0283;4.81
8.12;18300;0.0283;4.82
8.27;18300;0.0283;4.82
8.42;18200;0.0283;4.83
8.57;18200;0.0285;4.83
8.72;18100;0.0285;4.84
8.87;18000;0.0285;4.84
9.02;17800;0.0285;4.85
9.17;17600;0.0285;4.85
9.32;17300;0.0285;4.86
9.47;17000;0.0285;4.86
9.62;16700;0.0285;4.87
9.77;16400;0.0285;4.87
9.92;16100;0.0285;4.88
10.1;15800;0.0286;4.88
10.2;15400;0.0285;4.89
10.4;15000;0.0287;4.89
10.5;14700;0.0287;4.90
10.7;14300;0.0287;4.90
10.8;13900;0.0287;4.91
11.0;13400;0.0287;4.91
11.1;13000;0.0287;4.92
11.3;12500;0.0287;4.92
11.6;-138;0.0287;4.93